# Exceptions in C#

Exceptions (Ausnahmen) sind spezielle Objekte in C#, die bei Fehlern oder unerwartetem Verhalten zur Laufzeit auftreten und den normalen Programmfluss unterbrechen. Durch das Verwenden von Exceptions können Programme Fehler behandeln und eine kontrollierte Reaktion auslösen, anstatt das Programm abrupt zu beenden.

## Übersicht über Exceptions

In C# ist `Exception` die Basisklasse für alle Ausnahmearten. Andere häufig verwendete Ausnahme-Klassen sind:

- **SystemException**: Die Basisklasse für systembezogene Fehler.
- **ArgumentException**: Wird ausgelöst, wenn ein ungültiges Argument an eine Methode übergeben wird.
- **NullReferenceException**: Tritt auf, wenn auf eine nicht zugewiesene Objektreferenz zugegriffen wird.
- **InvalidOperationException**: Signalisiert einen ungültigen Aufruf von Methoden bei einem Objektzustand, der die Methode nicht zulässt.
- **IndexOutOfRangeException**: Tritt auf, wenn ein Array-Index außerhalb des gültigen Bereichs verwendet wird.
- **FileNotFoundException**: Wird ausgelöst, wenn versucht wird, auf eine Datei zuzugreifen, die nicht gefunden wurde.

## Exception Handling (Fehlerbehandlung) mit try-catch-finally

### Grundlegende Syntax

In C# wird der `try-catch-finally`-Block verwendet, um Ausnahmen zu behandeln:

```csharp
try
{
    // Code, der eine Exception auslösen könnte
}
catch (ExceptionType ex)
{
    // Code zur Behandlung der Exception
}
finally
{
    // Code, der immer ausgeführt wird, unabhängig davon, ob eine Exception auftrat
}
```

### Beispiel für try-catch-finally

```csharp
try
{
    int[] numbers = { 1, 2, 3 };
    Console.WriteLine(numbers[5]); // Dieser Zugriff wird eine IndexOutOfRangeException auslösen
}
catch (IndexOutOfRangeException ex)
{
    Console.WriteLine("Ein Fehler ist aufgetreten: " + ex.Message);
}
finally
{
    Console.WriteLine("Der finally-Block wird immer ausgeführt.");
}
```

### Mehrere catch-Blöcke

In C# können mehrere `catch`-Blöcke verwendet werden, um verschiedene Arten von Ausnahmen zu behandeln:

```csharp
try
{
    int number = int.Parse("abc"); // Wird eine FormatException auslösen
}
catch (FormatException ex)
{
    Console.WriteLine("Ungültiges Format: " + ex.Message);
}
catch (Exception ex)
{
    Console.WriteLine("Ein allgemeiner Fehler ist aufgetreten: " + ex.Message);
}
```

Um manche Exceptions zusammenfassen zu können, verwenden wir:
```csharp
try
{
    StreamReader reader = new StreamReader("example.txt");
    string content = reader.ReadToEnd();
}
catch (Exception ex) when (ex is FileNotFoundException || ex is DirectoryNotFoundException)
{
    Console.WriteLine("The required resource was not found. Attempting recovery.");
}
catch (Exception ex)
{
    Console.WriteLine("Ein allgemeiner Fehler ist aufgetreten: " + ex.Message);
}

Console.WriteLine("Dateiinhalt: " + content);
```
Versuche zudem nur Code im ``catch`` Block zu haben, welcher wirklich exceptions wirft. Falls dieser Code jedoch nicht ressourcenintensive ist, können diese auch im ``catch`` Block vorkommen. Ansonsten wirkt der Programmcode "zerstückelt". Hier haben wir ``Console.WriteLine("Dateiinhalt: " + content);`` außerhalb des ``catch`` Blockes.

Hier ist ``when`` ein Keyword welches nach einer Bedingung oder in diesem Fall bei catch, nach einer ``Exception`` angegeben werden kann. Danach folgt ein ``logischer Ausdruck`` welche die zuerst angegebene Exception verfeinert.
Es wird also eine ``Exception ex`` angeschaut, wenn diese vom Typ ``FileNotFoundExceptin`` oder ``DirecotryNotfoundException`` ist. 

Ein weiteres Beispiel für einschränkungen bei Exceptions ist folgendes:
```csharp
catch (SqlException ex) when (ex.Number == 547) // z.B. 547 ist Foreign key constraint violation. 547 sind SQL server Error Codes.
{
    Console.WriteLine("Foreign key constraint violated.");
}
```

## Benutzerdefinierte Exceptions

Benutzerdefinierte Exceptions können erstellt werden, indem von der Klasse `Exception` geerbt wird:

```csharp
public class InvalidUserException : Exception
{
    public InvalidUserException(string message) : base(message) { }
}
```

Verwendung der benutzerdefinierten Exception:

```csharp
public void ValidateUser(User user)
{
    if (user == null)
    {
        throw new InvalidUserException("Der Benutzer ist ungültig.");
    }
}
```

## Wiederwerfen von Exceptions

Eine Exception kann mit dem Schlüsselwort `throw` erneut ausgelöst werden, um sie an eine höhere Ebene weiterzugeben:

```csharp
try
{
    CheckUser(null);
}
catch (InvalidUserException ex)
{
    Console.WriteLine("Ein Benutzerfehler ist aufgetreten.");
    throw; // Wirft die Exception erneut
}
```

## Ausnahmeinformationen erweitern

Ein häufiger Ansatz zur Verbesserung der Fehlersuche besteht darin, eine innere Exception (`InnerException`) zu verwenden, um den ursprünglichen Fehlerkontext zu bewahren:

```csharp
try
{
    // Möglicherweise fehleranfälliger Code
}
catch (Exception ex)
{
    throw new InvalidOperationException("Eine Fehlermeldung", ex);
}
```
## Gibt es in C# ein `try-with-resources`-Äquivalent?

C# unterstützt kein `try-with-resources` wie in Java, aber es bietet die `using`-Anweisung, die dasselbe Ziel erreicht: Ressourcen automatisch zu schließen, sobald sie nicht mehr benötigt werden. Die `using`-Anweisung stellt sicher, dass das Objekt, das `IDisposable` implementiert (beispielsweise `StreamReader`, `FileStream`, und `SqlConnection`), freigegeben wird, auch wenn eine Exception auftritt.

### Beispiel mit `using`-Anweisung

```csharp
using System;
using System.IO;

public class Program
{
    public static void Main()
    {
        try
        {
            // Verwenden der `using`-Anweisung zur automatischen Freigabe der Ressource
            using (StreamReader reader = new StreamReader("example.txt"))
            {
                string content = reader.ReadToEnd();
                Console.WriteLine("Dateiinhalt: " + content);
            }
        }
        catch (FileNotFoundException ex)
        {
            Console.WriteLine("Fehler: Datei nicht gefunden. " + ex.Message);
        }
        catch (IOException ex)
        {
            Console.WriteLine("Fehler beim Lesen der Datei. " + ex.Message);
        }
    }
}
```

## Exception-Handling und Behebung des Fehlers

In diesem Beispiel wird ein Versuch gemacht, eine Datei zu speichern. Sollte dabei ein Problem auftreten, wird die Exception gefangen und der Inhalt in eine andere Datei geschrieben. Anschließend wird die Ressource geschlossen.

Ein ähnliches Beispiel könnte sein, wenn Excel in die cloud speichern will. Falls das nicht geht speichern wir den Inhalt der Datei vorher noch in eine temporäre Datei.

## Code-Beispiel

```csharp
using System;
using System.IO;

public class Program
{
   public static void Main()
    {
        string filePath = "output.txt";
        string content = "Das ist der Inhalt, der gespeichert werden soll.";

        try
        {
            // Versucht, in die ursprüngliche Datei zu schreiben
            using (StreamWriter writer = new StreamWriter(filePath))
            {
                writer.WriteLine(content);
                Console.WriteLine($"Inhalt erfolgreich in {filePath} gespeichert.");
            }
        }
        catch (IOException)
        {
            string tempFilePath = "temp_output.txt";

            Console.WriteLine("Warnung: Konnte nicht in die ursprüngliche Datei schreiben. Versuche, in die temporäre Datei zu schreiben.");

            try
            {
                // Versucht, in die temporäre Datei zu schreiben.
                // Stellen Sie sich vor, hier handelt es sich um ein anderes Laufwert, die Cloud oder ein Temporärer Ordner wo wahrscheinlicher ist, dass berechtigungen vorhanden sind.
                using (StreamWriter writer = new StreamWriter(tempFilePath))
                {
                    writer.WriteLine(content);
                    Console.WriteLine($"Inhalt erfolgreich in {tempFilePath} gespeichert.");
                }
            }
            catch (IOException)
            {
                // Finale Warnung, wenn auch das Schreiben in die temporäre Datei fehlschlägt
                Console.WriteLine("Fehler: Konnte den Inhalt weder in die ursprüngliche Datei noch in die temporäre Datei speichern.");
            }          
        }
    }
}
```


